<?xml version="1.0"?>
<!-- Revolute-Revolute Manipulator -->
<robot name="slave" xmlns:xacro="http://www.ros.org/wiki/xacro">

  <xacro:property name="height" value="2" /> <!-- 整体向上平移 -->
  <xacro:include filename="$(find slave_description)/urdf/slaved_arm.gazebo" />
  <xacro:include filename="$(find slave_description)/urdf/materials.xacro" />
  <!-- Import Rviz colors -->

<!--
   <material name="red">  
     <color rgba="0.8 0 0 1"/>  
   </material> 
   <material name="green">  
     <color rgba="0 0.8 0 1"/>  
   </material> 
   <material name="yellow">  
     <color rgba="1 1 0 1"/>  
   </material> 
   <material name="blue">  
     <color rgba="0 0 0.8 1"/>  
   </material> 
   <material name="qingse">  
     <color rgba="0 1 1 1"/>  
   </material> 
   <material name="purple">  
     <color rgba="0.5 0 0.5 1"/>  
   </material> 
   <material name="white">  
     <color rgba="1 1 1 1"/>  
   </material> 
-->
<!--   
   <gazebo>  
   	<plugin name="gazebo_ros_control" filename="libgazebo_ros_control.so">  
   		<robotNamespace>/testrobot</robotNamespace>  
   	</plugin>  
   </gazebo>
--> 
  <!-- Used for fixing robot to Gazebo 'base_link' -->
  <link name="world"/>

  <joint name="fixed" type="fixed">
  <origin
		  xyz="0 0 ${height}"
		  rpy="0 0 0" />
  <axis xyz="0 0 1" /> 
  <parent link="world"/>
  <child link="base_link"/>
  </joint>

  <link
    name="base_link">
    <inertial>
      <origin
        xyz="5.1774E-10 4.7942E-10 -0.0289093859119399"
        rpy="0 0 0" />
      <mass
       value="19.2423470449357" />

       <inertia
        ixx="1.83172730622602"
        ixy="-1.44586273709549E-05"
        ixz="-5.13937855858904E-10"
        iyy="1.82758773483675"
        iyz="-3.60851026785478E-10"
        izz="1.96009827090601" />
    </inertial>
<!--
      <inertia
        ixx="0.183172730622602"
        ixy="-1.44586273709549E-05"
        ixz="-5.13937855858904E-10"
        iyy="0.182758773483675"
        iyz="-3.60851026785478E-10"
        izz="0.196009827090601" />
    </inertial>
-->
    <visual>
      <origin
        xyz="0 0 0"
        rpy="0 0 0" />
      <geometry>
        <mesh
          filename="package://slaved_arm/meshes/base_link.STL" />
      </geometry>
      <material name="yellow"/>
    </visual>
    <collision>
      <origin
        xyz="0 0 0"
        rpy="0 0 0" />
      <geometry>
        <mesh
          filename="package://slaved_arm/meshes/base_link.STL" />
      </geometry>
    </collision>
  </link>
  <link
    name="arm1_Link">
    <inertial>
      <origin
        xyz="-1.0862E-08 2.35845982178003E-05 -0.0763992799985753"
        rpy="0 0 0" />
      <mass
        value="4.11490848445374" />
       <inertia
        ixx="0.152909987049032"
        ixy="-1.18950604606616E-09"
        ixz="-2.09495285576197E-09"
        iyy="0.0974380334758133"
        iyz="4.09987639089126E-06"
        izz="0.103107985034132" />
    </inertial>
<!--
      <inertia
        ixx="0.0152909987049032"
        ixy="-1.18950604606616E-09"
        ixz="-2.09495285576197E-09"
        iyy="0.00974380334758133"
        iyz="4.09987639089126E-06"
        izz="0.0103107985034132" />
    </inertial>
-->
    <visual>
      <origin
        xyz="0 0 0"
        rpy="0 0 0" />
      <geometry>
        <mesh
          filename="package://slaved_arm/meshes/arm1_Link.STL" />
      </geometry>

      <material name="red"/>
    </visual>
    <collision>
      <origin
        xyz="0 0 0"
        rpy="0 0 0" />
      <geometry>
        <mesh
          filename="package://slaved_arm/meshes/arm1_Link.STL" />
      </geometry>
    </collision>
  </link>
  <joint
    name="base_arm1_Joint"
    type="continuous">
    <origin
      xyz="0 0 -0.358"
      rpy="3.1416 6.3719E-14 -6.7352E-41" />
    <parent
      link="base_link" />
    <child
      link="arm1_Link" />
    <axis
      xyz="0 0 -1" />

    <dynamics damping="0" friciton ="0.0"/>
  </joint>
  <link
    name="arm2_Link">
    <inertial>
      <origin
        xyz="0.208911371772071 9.1124E-07 0.000685531981817064"
        rpy="0 0 0" />
      <mass
        value="6.6572" />
       <inertia
        ixx="0.12434"
        ixy="1.0679E-06"
        ixz="-0.0010418"
        iyy="1.626"
        iyz="2.7473E-09"
        izz="1.5375" />
    </inertial>
<!--
      <inertia
        ixx="0.012434"
        ixy="1.0679E-06"
        ixz="-0.0010418"
        iyy="0.1626"
        iyz="2.7473E-09"
        izz="0.15375" />
    </inertial>
-->
    <visual>
      <origin
        xyz="0 0 0"
        rpy="0 0 0" />
      <geometry>
        <mesh
          filename="package://slaved_arm/meshes/arm2_Link.STL" />
      </geometry>

      <material name="white"/>
    </visual>
    <collision>
      <origin
        xyz="0 0 0"
        rpy="0 0 0" />
      <geometry>
        <mesh
          filename="package://slaved_arm/meshes/arm2_Link.STL" />
      </geometry>
    </collision>
  </link>

  <joint
    name="arm1_arm2_Joint"
    type="continuous">
    <parent
      link="arm1_Link" />
    <child
      link="arm2_Link" />
    <origin
      xyz="0 0 0"
      rpy="1.5708 -1.5708 0" />
    <axis
      xyz="0 0 -1" />
    <dynamics damping="0" friciton ="0.0"/>

  </joint>
  <link
    name="arm3_Link">
    <inertial>
      <origin
        xyz="3.2621E-08 -0.0941668168419665 -0.00011161"
        rpy="0 0 0" />
      <mass
        value="3.6596" />
       <inertia
        ixx="0.15976"
        ixy="1.9452E-09"
        ixz="1.8581E-08"
        iyy="0.04441"
        iyz="3.8417E-05"
        izz="0.13599" />
    </inertial>
<!--
      <inertia
        ixx="0.015976"
        ixy="1.9452E-09"
        ixz="1.8581E-08"
        iyy="0.004441"
        iyz="3.8417E-05"
        izz="0.013599" />
    </inertial>
-->
    <visual>
      <origin
        xyz="0 0 0"
        rpy="0 0 0" />
      <geometry>
        <mesh
          filename="package://slaved_arm/meshes/arm3_Link.STL" />
      </geometry>
      <material name="green"/>
    </visual>
    <collision>
      <origin
        xyz="0 0 0"
        rpy="0 0 0" />
      <geometry>
        <mesh
          filename="package://slaved_arm/meshes/arm3_Link.STL" />
      </geometry>
    </collision>
  </link>
  <joint
    name="arm2_arm3_Joint"
    type="continuous">
    <origin
      xyz="0.4 0 0"
      rpy="1.8849E-16 4.2716E-14 1.5708" />
    <parent
      link="arm2_Link" />
    <child
      link="arm3_Link" />
    <axis
      xyz="0 0 -1" />
    <dynamics damping="0" friciton ="0.0"/>

     </joint>
  <link
    name="arm4_Link">
    <inertial>
      <origin
        xyz="2.122E-07 8.5298E-07 0.0354289838454891"
        rpy="0 0 0" />

       <!-- value="0.63863803" />-->
      <mass
        value="6.5501" />
       <inertia
        ixx="0.12297"
        ixy="-6.6807E-08"
        ixz="3.2045E-08"
        iyy="0.057908"
        iyz="1.2909E-07"
        izz="0.09209" />
    </inertial>
<!--
      <inertia
        ixx="0.012297"
        ixy="-6.6807E-08"
        ixz="3.2045E-08"
        iyy="0.0057908"
        iyz="1.2909E-07"
        izz="0.009209" />
    </inertial>
-->
    <visual>
      <origin
        xyz="0 0 0"
        rpy="0 0 0" />
      <geometry>
        <mesh
          filename="package://slaved_arm/meshes/arm4_Link.STL" />
      </geometry>
      <material name="purple"/>
    </visual>
    <collision>
      <origin
        xyz="0 0 0"
        rpy="0 0 0" />
      <geometry>
        <mesh
          filename="package://slaved_arm/meshes/arm4_Link.STL" />
      </geometry>
    </collision>
  </link>
  <joint
    name="arm3_arm4_Joint"
    type="continuous">
    <origin
      xyz="0 -0.3 0"
      rpy="-1.5708 0 -6.4115E-14" />
    <parent
      link="arm3_Link" />
    <child
      link="arm4_Link" />
    <axis
      xyz="0 0 1" />
    <dynamics damping="0" />

  </joint>

  <link
    name="arm5_Link">
    <inertial>
      <origin
        xyz="-4.8433E-10 -0.0289441655876508 5.5684E-05"
        rpy="0 0 0" />

      <!--  value="0.51409248" />-->
      <mass
        value="5.2728" />

       <inertia
        ixx="0.078562"
        ixy="-2.9471E-11"
        ixz="-1.2378E-09"
        iyy="0.049895"
        iyz="-8.4992E-06"
        izz="0.044435" />
    </inertial>
<!--
     <inertia
        ixx="0.0078562"
        ixy="-2.9471E-11"
        ixz="-1.2378E-09"
        iyy="0.0049895"
        iyz="-8.4992E-06"
        izz="0.0044435" />
    </inertial>
-->
    <visual>
      <origin
        xyz="0 0 0"
        rpy="0 0 0" />
      <geometry>
        <mesh
          filename="package://slaved_arm/meshes/arm5_Link.STL" />
      </geometry>
      <material name="turquoise"/>
    </visual>
    <collision>
      <origin
        xyz="0 0 0"
        rpy="0 0 0" />
      <geometry>
        <mesh
          filename="package://slaved_arm/meshes/arm5_Link.STL" />
      </geometry>
    </collision>
  </link>
  <joint
    name="arm4_arm5_Joint"
    type="continuous">
    <origin
      xyz="0 0 0"
      rpy="1.5708 -6.179E-14 5.5511E-16" />
    <parent
      link="arm4_Link" />
    <child
      link="arm5_Link" />
    <axis
      xyz="0 0 -1" />
    <dynamics damping="0" friciton ="0.0"/>
     </joint>
  <link
    name="arm6_Link">
    <inertial>
      <origin
        xyz="-3.578E-10 3.5543E-09 -0.0839113526842674"
        rpy="0 0 0" />

       <!-- value="0.14137511" />-->
      <mass
        value="3.625" />
       <inertia
        ixx="0.010012"
        ixy="-3.9595E-06"
        ixz="-7.6997E-12"
        iyy="0.0099373"
        iyz="7.583E-11"
        izz="0.007111" />
    </inertial>
<!--
     <inertia
        ixx="0.0010012"
        ixy="-3.9595E-06"
        ixz="-7.6997E-12"
        iyy="0.00099373"
        iyz="7.583E-11"
        izz="0.0007111" />
    </inertial>
-->
    <visual>
      <origin
        xyz="0 0 0"
        rpy="0 0 0" />
      <geometry>
        <mesh
          filename="package://slaved_arm/meshes/arm6_Link.STL" />
      </geometry>
      <material name="yellow"/>
    </visual>
    <collision>
      <origin
        xyz="0 0 0"
        rpy="0 0 0" />
      <geometry>
        <mesh
          filename="package://slaved_arm/meshes/arm6_Link.STL" />
      </geometry>
    </collision>
  </link>
  <joint
    name="arm5_arm6_Joint"
    type="continuous">
    <origin
      xyz="0 0 0"
      rpy="-1.5708 -1.4784E-15 -2.5244E-29" />
    <parent
      link="arm5_Link" />
    <child
      link="arm6_Link" />
    <axis
      xyz="0 0 1" />
    <dynamics damping="0" friciton ="0.0"/>

   </joint>
  <link
    name="gripperlink_Link">
    <inertial>
      <origin
        xyz="-1.471E-06 1.914E-10 -0.126671485145185"
        rpy="0 0 0" />
      <mass
        value="2.6735" />
       <inertia
        ixx="0.016484"
        ixy="-8.3113E-06"
        ixz="-9.1573E-09"
        iyy="0.015215"
        iyz="1.9346E-11"
        izz="0.0074558" />
    </inertial>
<!--
     <inertia
        ixx="0.0016484"
        ixy="-8.3113E-06"
        ixz="-9.1573E-09"
        iyy="0.0015215"
        iyz="1.9346E-11"
        izz="0.00074558" />
    </inertial>
-->
    <visual>
      <origin
        xyz="0 0 0"
        rpy="0 0 0" />
      <geometry>
        <mesh
          filename="package://slaved_arm/meshes/gripperlink_Link.STL" />
      </geometry>
      <material name="blue"/>
    </visual>
    <collision>
      <origin
        xyz="0 0 0"
        rpy="0 0 0" />
      <geometry>
        <mesh
          filename="package://slaved_arm/meshes/gripperlink_Link.STL" />
      </geometry>
    </collision>
  </link>
  <joint
    name="arm6_gripper_Joint"
    type="fixed">
    <origin
      xyz="0 0 0"
      rpy="-2.504E-31 0 0" />
    <parent
      link="arm6_Link" />
    <child
      link="gripperlink_Link" />
    <axis
      xyz="0 0 1" />
    <dynamics damping="0" friciton ="0.1"/>
<!--
	<limit lower="0.0"
		upper="0.0"
		effort="10.0"
		velocity="5.0" />
-->
  </joint>
  <link
    name="gripper_Link">
    <inertial>
      <origin
        xyz="1.7091E-05 -8.6029E-07 0.0737566585022837"
        rpy="0 0 0" />
      <mass
        value="3.6897" />
       <inertia
        ixx="0.022174"
        ixy="8.0632E-05"
        ixz="-1.5776E-06"
        iyy="0.015321"
        iyz="-2.0323E-07"
        izz="0.0092894" />
    </inertial>
<!--
      <inertia
        ixx="0.0022174"
        ixy="8.0632E-05"
        ixz="-1.5776E-06"
        iyy="0.0015321"
        iyz="-2.0323E-07"
        izz="0.00092894" />
    </inertial>
-->
    <visual>
      <origin
        xyz="0 0 0"
        rpy="0 0 0" />
      <geometry>
        <mesh
          filename="package://slaved_arm/meshes/gripper_Link.STL" />
      </geometry>

      <material name="red"/>
    </visual>
    <collision>
      <origin
        xyz="0 0 0"
        rpy="0 0 0" />
      <geometry>
        <mesh
          filename="package://slaved_arm/meshes/gripper_Link.STL" />
      </geometry>
    </collision>
  </link>
  <joint
    name="gripper_tool_Joint"
    type="fixed">
    <origin
      xyz="0 0 -0.25326"
      rpy="-1.7175E-14 4.478E-16 9.2326E-16" />
    <parent
      link="gripperlink_Link" />
    <child
      link="gripper_Link" />
    <axis
      xyz="0 0 0" />
    <dynamics damping="0" friciton ="0.1"/>
<!--
	<limit lower="0.0"
		upper="0.0"
		effort="10.0"
		velocity="5.0" />
-->
  </joint>


  <transmission name="tran1">
    <type>transmission_interface/SimpleTransmission</type>
    <joint name="base_arm1_Joint">
    <hardwareInterface>hardware_interface/PositionJointInterface</hardwareInterface>
    </joint>
    <actuator name="motor1">
      <hardwareInterface>hardware_interface/PostionJointInterface</hardwareInterface>
      <mechanicalReduction>1</mechanicalReduction>
    </actuator>
  </transmission>

  <transmission name="tran2">
    <type>transmission_interface/SimpleTransmission</type>
    <joint name="arm1_arm2_Joint">
      <hardwareInterface>hardware_interface/PositionJointInterface</hardwareInterface>
    </joint>
    <actuator name="motor2">
      <hardwareInterface>hardware_interface/PositionJointInterface</hardwareInterface>
      <mechanicalReduction>1</mechanicalReduction>
    </actuator>
  </transmission>

  <transmission name="tran3">
    <type>transmission_interface/SimpleTransmission</type>
    <joint name="arm2_arm3_Joint">
      <hardwareInterface>hardware_interface/PositionJointInterface</hardwareInterface>
    </joint>
    <actuator name="motor3">
      <hardwareInterface>hardware_interface/PositionJointInterface</hardwareInterface>
      <mechanicalReduction>1</mechanicalReduction>
    </actuator>
  </transmission>
  <transmission name="tran4">
    <type>transmission_interface/SimpleTransmission</type>
    <joint name="arm3_arm4_Joint">
      <hardwareInterface>hardware_interface/PositionJointInterface</hardwareInterface>
    </joint>
    <actuator name="motor4">
      <hardwareInterface>hardware_interface/PositionJointInterface</hardwareInterface>
      <mechanicalReduction>1</mechanicalReduction>
    </actuator>
  </transmission>
  <transmission name="tran5">
    <type>transmission_interface/SimpleTransmission</type>
    <joint name="arm4_arm5_Joint">
      <hardwareInterface>hardware_interface/PositionJointInterface</hardwareInterface>
    </joint>
    <actuator name="motor5">
      <hardwareInterface>hardware_interface/PositionJointInterface</hardwareInterface>
      <mechanicalReduction>1</mechanicalReduction>
    </actuator>
  </transmission>


  <transmission name="tran6">
    <type>transmission_interface/SimpleTransmission</type>
    <joint name="arm5_arm6_Joint">
      <hardwareInterface>hardware_interface/PositionJointInterface</hardwareInterface>
    </joint>
    <actuator name="motor6">
      <hardwareInterface>hardware_interface/PositionJointInterface</hardwareInterface>
      <mechanicalReduction>1</mechanicalReduction>
    </actuator>
  </transmission>


</robot>
