<?xml version="1.0"?>
<!-- Revolute-Revolute Manipulator -->
<robot name="ttrobot" xmlns:xacro="http://www.ros.org/wiki/xacro">

  <xacro:include filename="$(find testrobot_description)/urdf/slaved_arm.gazebo" />
  <!-- Import Rviz colors -->
  <xacro:include filename="$(find testrobot_description)/urdf/materials.xacro" />
<!--
   <material name="red">  
     <color rgba="0.8 0 0 1"/>  
   </material> 
   <material name="green">  
     <color rgba="0 0.8 0 1"/>  
   </material> 
   <material name="yellow">  
     <color rgba="1 1 0 1"/>  
   </material> 
   <material name="blue">  
     <color rgba="0 0 0.8 1"/>  
   </material> 
   <material name="qingse">  
     <color rgba="0 1 1 1"/>  
   </material> 
   <material name="purple">  
     <color rgba="0.5 0 0.5 1"/>  
   </material> 
   <material name="white">  
     <color rgba="1 1 1 1"/>  
   </material> 
-->

  <!-- Used for fixing robot to Gazebo 'base_link' -->
  <link name="world"/>

  <joint name="fixed" type="fixed">
  <parent link="world"/>
  <child link="base_link"/>
  </joint>

  <link
    name="base_link">
    <inertial>
      <origin
        xyz="-7.95293546843584E-09 1.61453493766593E-08 -0.0289093859119399"
        rpy="0 0 0" />
      <mass
        value="1.20264715542441" />
      <inertia
        ixx="0.0114482945563604"
        ixy="-9.02581399960635E-07"
        ixz="2.69938639635835E-10"
        iyy="0.0114224456415938"
        iyz="-7.5648739399688E-10"
        izz="0.0122506340331296" />
    </inertial>
    <visual>
      <origin
        xyz="0 0 0"
        rpy="0 0 0" />
      <geometry>
        <mesh
          filename="package://slaved_arm/meshes/base_link.STL" />
      </geometry>
        </visual>
    <collision>
      <origin
        xyz="0 0 0"
        rpy="0 0 0" />
      <geometry>
        <mesh
          filename="package://slaved_arm/meshes/base_link.STL" />
      </geometry>
    </collision>
  </link>
  <link
    name="arm1_Link">
    <inertial>
      <origin
        xyz="-4.83307956456774E-08 2.35845982178003E-05 -0.0763992799985753"
        rpy="0 0 0" />
      <mass
        value="0.257172609771794" />
      <inertia
        ixx="0.000955682753298614"
        ixy="-8.77862266834648E-11"
        ixz="-3.63217919734633E-10"
        iyy="0.000608970094648571"
        iyz="2.55532026419716E-07"
        izz="0.000644415680555199" />
    </inertial>
    <visual>
      <origin
        xyz="0 0 0"
        rpy="0 0 0" />
      <geometry>
        <mesh
          filename="package://slaved_arm/meshes/arm1_Link.STL" />
      </geometry>
    </visual>
    <collision>
      <origin
        xyz="0 0 0"
        rpy="0 0 0" />
      <geometry>
        <mesh
          filename="package://slaved_arm/meshes/arm1_Link.STL" />
      </geometry>
    </collision>
  </link>
  <joint
    name="base_arm1_Joint"
    type="revolute">
    <origin
      xyz="0 0 -0.358"
      rpy="3.1416 6.3719E-14 -6.7352E-41" />
    <parent
      link="base_link" />
    <child
      link="arm1_Link" />
    <axis
      xyz="0 0 -1" />

    <dynamics damping="0.0" friciton ="0"/>
    <limit
      lower="-6.2832"
      upper="6.2832"
      effort="0"
      velocity="0" />
  </joint>
  <link
    name="arm2_Link">
    <inertial>
      <origin
        xyz="0.208911371772071 9.09935239909388E-07 0.000685531981817064"
        rpy="0 0 0" />
      <mass
        value="0.416072694431116" />
      <inertia
        ixx="0.000777128033227915"
        ixy="6.67388195798242E-08"
        ixz="-6.51133295888731E-05"
        iyy="0.010162286739496"
        iyz="8.40072424868203E-12"
        izz="0.00960956475833455" />
    </inertial>
    <visual>
      <origin
        xyz="0 0 0"
        rpy="0 0 0" />
      <geometry>
        <mesh
          filename="package://slaved_arm/meshes/arm2_Link.STL" />
      </geometry>
    </visual>
    <collision>
      <origin
        xyz="0 0 0"
        rpy="0 0 0" />
      <geometry>
        <mesh
          filename="package://slaved_arm/meshes/arm2_Link.STL" />
      </geometry>
    </collision>
  </link>
  <joint
    name="arm1_arm2_Joint"
    type="revolute">
    <origin
      xyz="0 0 0"
      rpy="1.5708 -1.5708 0" />
    <parent
      link="arm1_Link" />
    <child
      link="arm2_Link" />
    <axis
      xyz="0 0 -1" />
    <dynamics damping="0.0" friciton ="0"/>
    <limit
      lower="-1.9199"
      upper="1.9199"
      effort="0"
      velocity="0" />
  </joint>
  <link
    name="arm3_Link">
    <inertial>
      <origin
        xyz="-8.34350226213717E-07 -0.0941668168419665 -0.000113662166744461"
        rpy="0 0 0" />
      <mass
        value="0.182975255835667" />
      <inertia
        ixx="0.000798832921574669"
        ixy="2.55096406098312E-09"
        ixz="1.28236572886389E-08"
        iyy="0.00022207387184464"
        iyz="1.92431786200013E-06"
        izz="0.000679936198585923" />
    </inertial>
    <visual>
      <origin
        xyz="0 0 0"
        rpy="0 0 0" />
      <geometry>
        <mesh
          filename="package://slaved_arm/meshes/arm3_Link.STL" />
      </geometry>
    </visual>
    <collision>
      <origin
        xyz="0 0 0"
        rpy="0 0 0" />
      <geometry>
        <mesh
          filename="package://slaved_arm/meshes/arm3_Link.STL" />
      </geometry>
    </collision>
  </link>
  <joint
    name="arm2_arm3_Joint"
    type="revolute">
    <origin
      xyz="0.4 0 0"
      rpy="1.8849E-16 4.2716E-14 1.5708" />
    <parent
      link="arm2_Link" />
    <child
      link="arm3_Link" />
    <axis
      xyz="0 0 -1" />
    <dynamics damping="0.0" friciton ="0"/>
    <limit
      lower="-1.9199"
      upper="1.9199"
      effort="0"
      velocity="0" />
  </joint>
  <link
    name="arm4_Link">
    <inertial>
      <origin
        xyz="2.10633227704038E-07 8.3899748441661E-07 0.0354289838454891"
        rpy="0 0 0" />
      <mass
        value="0.0818766807497932" />
      <inertia
        ixx="0.000153711758335827"
        ixy="2.43033526708693E-10"
        ixz="4.01436502480997E-10"
        iyy="7.23858739701422E-05"
        iyz="1.62233394693944E-09"
        izz="0.000115115645489281" />
    </inertial>
    <visual>
      <origin
        xyz="0 0 0"
        rpy="0 0 0" />
      <geometry>
        <mesh
          filename="package://slaved_arm/meshes/arm4_Link.STL" />
      </geometry>
    </visual>
    <collision>
      <origin
        xyz="0 0 0"
        rpy="0 0 0" />
      <geometry>
        <mesh
          filename="package://slaved_arm/meshes/arm4_Link.STL" />
      </geometry>
    </collision>
  </link>
  <joint
    name="arm3_arm4_Joint"
    type="revolute">
    <origin
      xyz="0 -0.3 0"
      rpy="-1.5708 0 -6.4115E-14" />
    <parent
      link="arm3_Link" />
    <child
      link="arm4_Link" />
    <axis
      xyz="0 0 1" />
    <dynamics damping="0.0" friciton ="0"/>
    <limit
      lower="-6.2832"
      upper="6.2832"
      effort="0"
      velocity="0" />
  </joint>
  <link
    name="arm5_Link">
    <inertial>
      <origin
        xyz="-5.88661109512881E-09 -0.0289441655876508 5.56712199455193E-05"
        rpy="0 0 0" />
      <mass
        value="0.0659092868280022" />
      <inertia
        ixx="9.82045245344719E-05"
        ixy="-3.18310545478071E-12"
        ixz="2.86935284698526E-10"
        iyy="6.23696264444831E-05"
        iyz="-1.06246898632282E-07"
        izz="5.55424499529875E-05" />
    </inertial>
    <visual>
      <origin
        xyz="0 0 0"
        rpy="0 0 0" />
      <geometry>
        <mesh
          filename="package://slaved_arm/meshes/arm5_Link.STL" />
      </geometry>
    </visual>
    <collision>
      <origin
        xyz="0 0 0"
        rpy="0 0 0" />
      <geometry>
        <mesh
          filename="package://slaved_arm/meshes/arm5_Link.STL" />
      </geometry>
    </collision>
  </link>
  <joint
    name="arm4_arm5_Joint"
    type="revolute">
    <origin
      xyz="0 0 0"
      rpy="1.5708 -6.179E-14 5.5511E-16" />
    <parent
      link="arm4_Link" />
    <child
      link="arm5_Link" />
    <axis
      xyz="0 0 -1" />
    <dynamics damping="0.0" friciton ="0"/>
    <limit
      lower="-1.9199"
      upper="1.9199"
      effort="0"
      velocity="0" />
  </joint>
  <link
    name="arm6_Link">
    <inertial>
      <origin
        xyz="-1.75625732595499E-10 4.23280374847944E-09 -0.0839113526842674"
        rpy="0 0 0" />
      <mass
        value="0.0181250137704112" />
      <inertia
        ixx="5.00576775822878E-06"
        ixy="-1.97980075433518E-08"
        ixz="-4.01712354773005E-14"
        iyy="4.96864932688489E-06"
        iyz="3.99904276387492E-13"
        izz="3.55553226698005E-06" />
    </inertial>
    <visual>
      <origin
        xyz="0 0 0"
        rpy="0 0 0" />
      <geometry>
        <mesh
          filename="package://slaved_arm/meshes/arm6_Link.STL" />
      </geometry>
    </visual>
    <collision>
      <origin
        xyz="0 0 0"
        rpy="0 0 0" />
      <geometry>
        <mesh
          filename="package://slaved_arm/meshes/arm6_Link.STL" />
      </geometry>
    </collision>
  </link>
  <joint
    name="arm5_arm6_Joint"
    type="revolute">
    <origin
      xyz="0 0 0"
      rpy="-1.5708 -1.4784E-15 -2.5244E-29" />
    <parent
      link="arm5_Link" />
    <child
      link="arm6_Link" />
    <axis
      xyz="0 0 1" />
    <dynamics damping="0.0" friciton ="0"/>
    <limit
      lower="-6.2832"
      upper="6.2832"
      effort="0"
      velocity="0" />
  </joint>
  <link
    name="gripperlink_Link">
    <inertial>
      <origin
        xyz="-1.46939885263755E-06 -5.88890488927326E-09 -0.126671485145185"
        rpy="0 0 0" />
      <mass
        value="0.0334193393830534" />
      <inertia
        ixx="2.06054312981301E-05"
        ixy="-1.03887710279876E-07"
        ixz="-1.14732065242752E-10"
        iyy="1.90182298425498E-05"
        iyz="3.16197727963367E-12"
        izz="9.3197615889823E-06" />
    </inertial>
    <visual>
      <origin
        xyz="0 0 0"
        rpy="0 0 0" />
      <geometry>
        <mesh
          filename="package://slaved_arm/meshes/gripperlink_Link.STL" />
      </geometry>
    </visual>
    <collision>
      <origin
        xyz="0 0 0"
        rpy="0 0 0" />
      <geometry>
        <mesh
          filename="package://slaved_arm/meshes/gripperlink_Link.STL" />
      </geometry>
    </collision>
  </link>
  <joint
    name="arm6_gripper_Joint"
    type="fixed">
    <origin
      xyz="0 0 0"
      rpy="-2.504E-31 0 0" />
    <parent
      link="arm6_Link" />
    <child
      link="gripperlink_Link" />
    <axis
      xyz="0 0 1" />
    <dynamics damping="0.0" friciton ="0"/>
  </joint>
  <link
    name="gripper_Link">
    <inertial>
      <origin
        xyz="1.7091335099308E-05 -8.60361072437395E-07 0.0737566585022837"
        rpy="0 0 0" />
      <mass
        value="0.0184484818702842" />
      <inertia
        ixx="1.10865775587346E-05"
        ixy="4.0316347382212E-07"
        ixz="-7.88784128893263E-09"
        iyy="7.66024442326954E-06"
        iyz="-1.01617022368791E-09"
        izz="4.64467771666913E-06" />
    </inertial>
    <visual>
      <origin
        xyz="0 0 0"
        rpy="0 0 0" />
      <geometry>
        <mesh
          filename="package://slaved_arm/meshes/gripper_Link.STL" />
      </geometry>
    </visual>
    <collision>
      <origin
        xyz="0 0 0"
        rpy="0 0 0" />
      <geometry>
        <mesh
          filename="package://slaved_arm/meshes/gripper_Link.STL" />
      </geometry>
    </collision>
  </link>
  <joint
    name="gripper_tool_Joint"
    type="fixed">
    <origin
      xyz="0 0 -0.25326"
      rpy="-1.7175E-14 4.478E-16 9.2326E-16" />
    <parent
      link="gripperlink_Link" />
    <child
      link="gripper_Link" />
    <axis
      xyz="0 0 0" />
    <dynamics damping="0.0" friciton ="0"/>
  </joint>

</robot>
